Workbook

Sheet 使用說明
A1: SCIONX Destuff 互動練習 -- 真實 Frame 版 ver2 實驗版 (延伸自 scionx_destuff_demo.xlsx 的機制，跟 04d_destuff_interactive.py 主版本平行比較用)
A3: 這份檔案把 scionx_destuff_demo.xlsx 驗證過的機制（RawBits 下拉選單 destuff/flip -> 其他分頁即時連動）套用到 cut_first3.ogg 真實訊號解出的 Frame #2，共 2240 個原始判決 bit（不含結尾額外顯示的 40 bit）。
A5: 這是 04d_destuff_interactive_ver2.py 產生的檔案，跟主版本 04d_destuff_interactive.py （輸出檔名沒有 _ver2）內容大部分一樣，差別只在下面 ver2 專屬的第 5、6 點 -- 兩個檔案可以同時開著比較。
A7: 改動（相對於最早的手動 demo 版）：
A8: 1. ExcludeThisBit / FlipThisBit 這兩欄現在全部預設 No，不再由程式先猜答案 -- 要 destuff/flip 哪個 bit，完全由你自己判斷、手動勾選。
A9: 2. LowConfidence、CandidateStuffPoint 這兩欄，只要是 Yes 就用紅字標出來（這兩欄是根據這一列固定的採樣點/RawBitValue 算的，不會因為你調整別的列而變動）。
A10: 3. 拿掉 Destuffed、Bytes_Hex 兩個分頁（比對介面太雜，容易搞混）。CRC_Check 保留。
A11: 4. 新增 Beacon Decode 分頁，樣式跟舊的 cut_first3_frame2_beacon_decode.xlsx 一樣（Subsystem/ItemName/OffsetBit/BitLen/Bits/ReadableValue/LookupTable，同欄位的 bit 合併成一列），會隨你在 RawBits 的調整即時連動。
A12: 5.（ver2 專屬實驗）_DestuffedBits 分頁改成不隱藏，直接放在 RawBits 右邊。這是「移位後的壓縮序列」本尊：Position 欄永遠代表『目前存活的第幾個 bit』，你在 RawBits 排除一個 bit 後，後面所有 Position 對應到的 RawBits 來源列（B欄 SourceRawBitIndex）跟數值都會往前挪一格 -- 這是跟 RawBits 本身『每列固定代表一個採樣點、Subsystem/ItemName/ReadableValue 隨 DestuffedSeqNo 查表變動』相反的呈現方式，同一份資料兩種看法，可以互相對照。D/E 欄（Subsystem/ItemName）是額外加的，純粹讓你在看數值滑動時知道滑到哪個欄位了。
A13: 6.（ver2 專屬）header 區段的邊界從 14 bytes 修正成 16 bytes（含 Control+PID），跟 Beacon Decode 的 HEADER 四列對齊。
A14: 7.（ver2 專屬實驗）RawBits 的整列背景色改成用 Excel 條件式格式設定即時算，不再是產生檔案當下就寫死的固定色：ExcludeThisBit=Yes 的列會整列變黃色（優先權最高，一眼就能看出你已經處理過哪些列）；其餘列的顏色跟著 I 欄 SegmentGuess 走 -- 而 SegmentGuess 本身現在也是活公式，根據這一列『當下』的 H 欄（DestuffedSeqNo）落在哪個結構段（address/data1/zero-run1/data2/zero-run2/FCS/trailing）決定，跟 J~M 欄同一套邏輯。結果就是：你在前面排除一個 bit 之後，後面每一列的『顏色』會跟著『欄位名稱』一起往前移動一格，不是只有文字變、顏色沒動。你還沒排除任何東西之前，顏色顯示的是『假設完全沒 destuff』的樸素結構猜測（跟 J~M 欄一開始的行為一樣），這是預期行為，不是 bug。
A16: 比對用的參考資料是 REFERENCE_FRAME.md 的 272-byte 地面測試封包（同一顆衛星的另一次下傳）。根據 CLAUDE.md 的規則：header（Dest/Src address + Control + PID，前 16 bytes）以及 Info 欄位裡的長段全零 padding，在任何一次下傳中理論上都應該相同；但 Info 欄位裡真正的遙測數值（data1/data2 兩段）每個 frame 都不一樣，這份參考資料涵蓋 1320 bit 的 header/zero-run，另外 872 bit 的 telemetry 沒有真值可比對，只能靠 CRC_Check 驗證。這份參考資料目前只用在：(a) 內部訊號判決時決定 zero-run 段要用哪一種門檻規則（RawBits 的 SegmentGuess 欄），(b) 對齊 offset 的小範圍搜尋。不會用來預先決定你的 ExcludeThisBit / FlipThisBit。
... A27: 效能提醒：這個檔案有兩千多列公式，Excel 開啟、或每次改動下拉選單重新計算，都會比 demo 檔慢一點，屬正常現象。另外有兩個分頁（_DestuffedBits、Fields）被隱藏了，是內部串接用的輔助分頁（RawBits/Beacon Decode/CRC_Check 都是靠它們對齊資料），好奇可以在分頁標籤按右鍵「取消隱藏」看，但不需要去動裡面的內容。

Sheet RawBits
A1: BitIndex | B1: RawBitValue | C1: LowConfidence | D1: CandidateStuffPoint | E1: ExcludeThisBit | F1: FlipThisBit | G1: EffectiveBitValue | H1: DestuffedSeqNo | I1: SegmentGuess | J1: Subsystem | K1: ItemName | L1: ReadableValue | M1: LookupTable
A2: 0 | B2: 0 | C2: No | E2: No | F2: No | G2: =IF(F2="Yes",1-B2,B2) | H2: =IF(E2="Yes","",COUNTIFS($E$2:E2,"No")) | I2: =IF(H2="","",IF(H2<=128,"address",IF(H2<=600,"data1",IF(H2<=1264,"zero-run1",IF(H2<=1648,"data2",IF(H2<=2176,"zero-run2",IF(H2<=2192,"FCS","trailing"))))))) | J2: =IFERROR(IF(AND(H2<>"",H2>=129,H2<=2176),INDEX(Fields!$B$2:$B$206,MATCH(H2-129,Fields!$D$2:$D$206,1)),""),"") | K2: =IFERROR(IF(AND(H2<>"",H2>=129,H2<=2176),INDEX(Fields!$C$2:$C$206,MATCH(H2-129,Fields!$D$2:$D$206,1)),""),"") | L2: =IFERROR(IF(AND(H2<>"",H2>=129,H2<=2176),INDEX(Fields!$J$2:$J$206,MATCH(H2-129,Fields!$D$2:$D$206,1)),""),"") | M2: =IFERROR(IF(AND(H2<>"",H2>=129,H2<=2176),INDEX(Fields!$K$2:$K$206,MATCH(H2-129,Fields!$D$2:$D$206,1)),""),"")
A3: 1 | B3: 0 | C3: No | E3: No | F3: No | G3: =IF(F3="Yes",1-B3,B3) | H3: =IF(E3="Yes","",COUNTIFS($E$2:E3,"No")) | I3: =IF(H3="","",IF(H3<=128,"address",IF(H3<=600,"data1",IF(H3<=1264,"zero-run1",IF(H3<=1648,"data2",IF(H3<=2176,"zero-run2",IF(H3<=2192,"FCS","trailing"))))))) | J3: =IFERROR(IF(AND(H3<>"",H3>=129,H3<=2176),INDEX(Fields!$B$2:$B$206,MATCH(H3-129,Fields!$D$2:$D$206,1)),""),"") | K3: =IFERROR(IF(AND(H3<>"",H3>=129,H3<=2176),INDEX(Fields!$C$2:$C$206,MATCH(H3-129,Fields!$D$2:$D$206,1)),""),"") | L3: =IFERROR(IF(AND(H3<>"",H3>=129,H3<=2176),INDEX(Fields!$J$2:$J$206,MATCH(H3-129,Fields!$D$2:$D$206,1)),""),"") | M3: =IFERROR(IF(AND(H3<>"",H3>=129,H3<=2176),INDEX(Fields!$K$2:$K$206,MATCH(H3-129,Fields!$D$2:$D$206,1)),""),"")
A4: 2 | B4: 1 | C4: No | E4: No | F4: No | G4: =IF(F4="Yes",1-B4,B4) | H4: =IF(E4="Yes","",COUNTIFS($E$2:E4,"No")) | I4: =IF(H4="","",IF(H4<=128,"address",IF(H4<=600,"data1",IF(H4<=1264,"zero-run1",IF(H4<=1648,"data2",IF(H4<=2176,"zero-run2",IF(H4<=2192,"FCS","trailing"))))))) | J4: =IFERROR(IF(AND(H4<>"",H4>=129,H4<=2176),INDEX(Fields!$B$2:$B$206,MATCH(H4-129,Fields!$D$2:$D$206,1)),""),"") | K4: =IFERROR(IF(AND(H4<>"",H4>=129,H4<=2176),INDEX(Fields!$C$2:$C$206,MATCH(H4-129,Fields!$D$2:$D$206,1)),""),"") | L4: =IFERROR(IF(AND(H4<>"",H4>=129,H4<=2176),INDEX(Fields!$J$2:$J$206,MATCH(H4-129,Fields!$D$2:$D$206,1)),""),"") | M4: =IFERROR(IF(AND(H4<>"",H4>=129,H4<=2176),INDEX(Fields!$K$2:$K$206,MATCH(H4-129,Fields!$D$2:$D$206,1)),""),"")
A5: 3 | B5: 0 | C5: No | E5: No | F5: No | G5: =IF(F5="Yes",1-B5,B5) | H5: =IF(E5="Yes","",COUNTIFS($E$2:E5,"No")) | I5: =IF(H5="","",IF(H5<=128,"address",IF(H5<=600,"data1",IF(H5<=1264,"zero-run1",IF(H5<=1648,"data2",IF(H5<=2176,"zero-run2",IF(H5<=2192,"FCS","trailing"))))))) | J5: =IFERROR(IF(AND(H5<>"",H5>=129,H5<=2176),INDEX(Fields!$B$2:$B$206,MATCH(H5-129,Fields!$D$2:$D$206,1)),""),"") | K5: =IFERROR(IF(AND(H5<>"",H5>=129,H5<=2176),INDEX(Fields!$C$2:$C$206,MATCH(H5-129,Fields!$D$2:$D$206,1)),""),"") | L5: =IFERROR(IF(AND(H5<>"",H5>=129,H5<=2176),INDEX(Fields!$J$2:$J$206,MATCH(H5-129,Fields!$D$2:$D$206,1)),""),"") | M5: =IFERROR(IF(AND(H5<>"",H5>=129,H5<=2176),INDEX(Fields!$K$2:$K$206,MATCH(H5-129,Fields!$D$2:$D$206,1)),""),"")
A6: 4 | B6: 0 | C6: Yes | E6: No | F6: No | G6: =IF(F6="Yes",1-B6,B6) | H6: =IF(E6="Yes","",COUNTIFS($E$2:E6,"No")) | I6: =IF(H6="","",IF(H6<=128,"address",IF(H6<=600,"data1",IF(H6<=1264,"zero-run1",IF(H6<=1648,"data2",IF(H6<=2176,"zero-run2",IF(H6<=2192,"FCS","trailing"))))))) | J6: =IFERROR(IF(AND(H6<>"",H6>=129,H6<=2176),INDEX(Fields!$B$2:$B$206,MATCH(H6-129,Fields!$D$2:$D$206,1)),""),"") | K6: =IFERROR(IF(AND(H6<>"",H6>=129,H6<=2176),INDEX(Fields!$C$2:$C$206,MATCH(H6-129,Fields!$D$2:$D$206,1)),""),"") | L6: =IFERROR(IF(AND(H6<>"",H6>=129,H6<=2176),INDEX(Fields!$J$2:$J$206,MATCH(H6-129,Fields!$D$2:$D$206,1)),""),"") | M6: =IFERROR(IF(AND(H6<>"",H6>=129,H6<=2176),INDEX(Fields!$K$2:$K$206,MATCH(H6-129,Fields!$D$2:$D$206,1)),""),"")
A7: 5 | B7: 0 | C7: No | D7: =IF(AND(B2=1,B3=1,B4=1,B5=1,B6=1),"Yes","") | E7: No | F7: No | G7: =IF(F7="Yes",1-B7,B7) | H7: =IF(E7="Yes","",COUNTIFS($E$2:E7,"No")) | I7: =IF(H7="","",IF(H7<=128,"address",IF(H7<=600,"data1",IF(H7<=1264,"zero-run1",IF(H7<=1648,"data2",IF(H7<=2176,"zero-run2",IF(H7<=2192,"FCS","trailing"))))))) | J7: =IFERROR(IF(AND(H7<>"",H7>=129,H7<=2176),INDEX(Fields!$B$2:$B$206,MATCH(H7-129,Fields!$D$2:$D$206,1)),""),"") | K7: =IFERROR(IF(AND(H7<>"",H7>=129,H7<=2176),INDEX(Fields!$C$2:$C$206,MATCH(H7-129,Fields!$D$2:$D$206,1)),""),"") | L7: =IFERROR(IF(AND(H7<>"",H7>=129,H7<=2176),INDEX(Fields!$J$2:$J$206,MATCH(H7-129,Fields!$D$2:$D$206,1)),""),"") | M7: =IFERROR(IF(AND(H7<>"",H7>=129,H7<=2176),INDEX(Fields!$K$2:$K$206,MATCH(H7-129,Fields!$D$2:$D$206,1)),""),"")
A8: 6 | B8: 0 | C8: No | D8: =IF(AND(B3=1,B4=1,B5=1,B6=1,B7=1),"Yes","") | E8: No | F8: No | G8: =IF(F8="Yes",1-B8,B8) | H8: =IF(E8="Yes","",COUNTIFS($E$2:E8,"No")) | I8: =IF(H8="","",IF(H8<=128,"address",IF(H8<=600,"data1",IF(H8<=1264,"zero-run1",IF(H8<=1648,"data2",IF(H8<=2176,"zero-run2",IF(H8<=2192,"FCS","trailing"))))))) | J8: =IFERROR(IF(AND(H8<>"",H8>=129,H8<=2176),INDEX(Fields!$B$2:$B$206,MATCH(H8-129,Fields!$D$2:$D$206,1)),""),"") | K8: =IFERROR(IF(AND(H8<>"",H8>=129,H8<=2176),INDEX(Fields!$C$2:$C$206,MATCH(H8-129,Fields!$D$2:$D$206,1)),""),"") | L8: =IFERROR(IF(AND(H8<>"",H8>=129,H8<=2176),INDEX(Fields!$J$2:$J$206,MATCH(H8-129,Fields!$D$2:$D$206,1)),""),"") | M8: =IFERROR(IF(AND(H8<>"",H8>=129,H8<=2176),INDEX(Fields!$K$2:$K$206,MATCH(H8-129,Fields!$D$2:$D$206,1)),""),"")
A9: 7 | B9: 1 | C9: No | D9: =IF(AND(B4=1,B5=1,B6=1,B7=1,B8=1),"Yes","") | E9: No | F9: No | G9: =IF(F9="Yes",1-B9,B9) | H9: =IF(E9="Yes","",COUNTIFS($E$2:E9,"No")) | I9: =IF(H9="","",IF(H9<=128,"address",IF(H9<=600,"data1",IF(H9<=1264,"zero-run1",IF(H9<=1648,"data2",IF(H9<=2176,"zero-run2",IF(H9<=2192,"FCS","trailing"))))))) | J9: =IFERROR(IF(AND(H9<>"",H9>=129,H9<=2176),INDEX(Fields!$B$2:$B$206,MATCH(H9-129,Fields!$D$2:$D$206,1)),""),"") | K9: =IFERROR(IF(AND(H9<>"",H9>=129,H9<=2176),INDEX(Fields!$C$2:$C$206,MATCH(H9-129,Fields!$D$2:$D$206,1)),""),"") | L9: =IFERROR(IF(AND(H9<>"",H9>=129,H9<=2176),INDEX(Fields!$J$2:$J$206,MATCH(H9-129,Fields!$D$2:$D$206,1)),""),"") | M9: =IFERROR(IF(AND(H9<>"",H9>=129,H9<=2176),INDEX(Fields!$K$2:$K$206,MATCH(H9-129,Fields!$D$2:$D$206,1)),""),"")
A10: 8 | B10: 0 | C10: No | D10: =IF(AND(B5=1,B6=1,B7=1,B8=1,B9=1),"Yes","") | E10: No | F10: No | G10: =IF(F10="Yes",1-B10,B10) | H10: =IF(E10="Yes","",COUNTIFS($E$2:E10,"No")) | I10: =IF(H10="","",IF(H10<=128,"address",IF(H10<=600,"data1",IF(H10<=1264,"zero-run1",IF(H10<=1648,"data2",IF(H10<=2176,"zero-run2",IF(H10<=2192,"FCS","trailing"))))))) | J10: =IFERROR(IF(AND(H10<>"",H10>=129,H10<=2176),INDEX(Fields!$B$2:$B$206,MATCH(H10-129,Fields!$D$2:$D$206,1)),""),"") | K10: =IFERROR(IF(AND(H10<>"",H10>=129,H10<=2176),INDEX(Fields!$C$2:$C$206,MATCH(H10-129,Fields!$D$2:$D$206,1)),""),"") | L10: =IFERROR(IF(AND(H10<>"",H10>=129,H10<=2176),INDEX(Fields!$J$2:$J$206,MATCH(H10-129,Fields!$D$2:$D$206,1)),""),"") | M10: =IFERROR(IF(AND(H10<>"",H10>=129,H10<=2176),INDEX(Fields!$K$2:$K$206,MATCH(H10-129,Fields!$D$2:$D$206,1)),""),"")
A11: 9 | B11: 0 | C11: No | D11: =IF(AND(B6=1,B7=1,B8=1,B9=1,B10=1),"Yes","") | E11: No | F11: No | G11: =IF(F11="Yes",1-B11,B11) | H11: =IF(E11="Yes","",COUNTIFS($E$2:E11,"No")) | I11: =IF(H11="","",IF(H11<=128,"address",IF(H11<=600,"data1",IF(H11<=1264,"zero-run1",IF(H11<=1648,"data2",IF(H11<=2176,"zero-run2",IF(H11<=2192,"FCS","trailing"))))))) | J11: =IFERROR(IF(AND(H11<>"",H11>=129,H11<=2176),INDEX(Fields!$B$2:$B$206,MATCH(H11-129,Fields!$D$2:$D$206,1)),""),"") | K11: =IFERROR(IF(AND(H11<>"",H11>=129,H11<=2176),INDEX(Fields!$C$2:$C$206,MATCH(H11-129,Fields!$D$2:$D$206,1)),""),"") | L11: =IFERROR(IF(AND(H11<>"",H11>=129,H11<=2176),INDEX(Fields!$J$2:$J$206,MATCH(H11-129,Fields!$D$2:$D$206,1)),""),"") | M11: =IFERROR(IF(AND(H11<>"",H11>=129,H11<=2176),INDEX(Fields!$K$2:$K$206,MATCH(H11-129,Fields!$D$2:$D$206,1)),""),"")
A12: 10 | B12: 1 | C12: No | D12: =IF(AND(B7=1,B8=1,B9=1,B10=1,B11=1),"Yes","") | E12: No | F12: No | G12: =IF(F12="Yes",1-B12,B12) | H12: =IF(E12="Yes","",COUNTIFS($E$2:E12,"No")) | I12: =IF(H12="","",IF(H12<=128,"address",IF(H12<=600,"data1",IF(H12<=1264,"zero-run1",IF(H12<=1648,"data2",IF(H12<=2176,"zero-run2",IF(H12<=2192,"FCS","trailing"))))))) | J12: =IFERROR(IF(AND(H12<>"",H12>=129,H12<=2176),INDEX(Fields!$B$2:$B$206,MATCH(H12-129,Fields!$D$2:$D$206,1)),""),"") | K12: =IFERROR(IF(AND(H12<>"",H12>=129,H12<=2176),INDEX(Fields!$C$2:$C$206,MATCH(H12-129,Fields!$D$2:$D$206,1)),""),"") | L12: =IFERROR(IF(AND(H12<>"",H12>=129,H12<=2176),INDEX(Fields!$J$2:$J$206,MATCH(H12-129,Fields!$D$2:$D$206,1)),""),"") | M12: =IFERROR(IF(AND(H12<>"",H12>=129,H12<=2176),INDEX(Fields!$K$2:$K$206,MATCH(H12-129,Fields!$D$2:$D$206,1)),""),"")
A13: 11 | B13: 1 | C13: No | D13: =IF(AND(B8=1,B9=1,B10=1,B11=1,B12=1),"Yes","") | E13: No | F13: No | G13: =IF(F13="Yes",1-B13,B13) | H13: =IF(E13="Yes","",COUNTIFS($E$2:E13,"No")) | I13: =IF(H13="","",IF(H13<=128,"address",IF(H13<=600,"data1",IF(H13<=1264,"zero-run1",IF(H13<=1648,"data2",IF(H13<=2176,"zero-run2",IF(H13<=2192,"FCS","trailing"))))))) | J13: =IFERROR(IF(AND(H13<>"",H13>=129,H13<=2176),INDEX(Fields!$B$2:$B$206,MATCH(H13-129,Fields!$D$2:$D$206,1)),""),"") | K13: =IFERROR(IF(AND(H13<>"",H13>=129,H13<=2176),INDEX(Fields!$C$2:$C$206,MATCH(H13-129,Fields!$D$2:$D$206,1)),""),"") | L13: =IFERROR(IF(AND(H13<>"",H13>=129,H13<=2176),INDEX(Fields!$J$2:$J$206,MATCH(H13-129,Fields!$D$2:$D$206,1)),""),"") | M13: =IFERROR(IF(AND(H13<>"",H13>=129,H13<=2176),INDEX(Fields!$K$2:$K$206,MATCH(H13-129,Fields!$D$2:$D$206,1)),""),"")
A14: 12 | B14: 1 | C14: No | D14: =IF(AND(B9=1,B10=1,B11=1,B12=1,B13=1),"Yes","") | E14: No | F14: No | G14: =IF(F14="Yes",1-B14,B14) | H14: =IF(E14="Yes","",COUNTIFS($E$2:E14,"No")) | I14: =IF(H14="","",IF(H14<=128,"address",IF(H14<=600,"data1",IF(H14<=1264,"zero-run1",IF(H14<=1648,"data2",IF(H14<=2176,"zero-run2",IF(H14<=2192,"FCS","trailing"))))))) | J14: =IFERROR(IF(AND(H14<>"",H14>=129,H14<=2176),INDEX(Fields!$B$2:$B$206,MATCH(H14-129,Fields!$D$2:$D$206,1)),""),"") | K14: =IFERROR(IF(AND(H14<>"",H14>=129,H14<=2176),INDEX(Fields!$C$2:$C$206,MATCH(H14-129,Fields!$D$2:$D$206,1)),""),"") | L14: =IFERROR(IF(AND(H14<>"",H14>=129,H14<=2176),INDEX(Fields!$J$2:$J$206,MATCH(H14-129,Fields!$D$2:$D$206,1)),""),"") | M14: =IFERROR(IF(AND(H14<>"",H14>=129,H14<=2176),INDEX(Fields!$K$2:$K$206,MATCH(H14-129,Fields!$D$2:$D$206,1)),""),"")
A15: 13 | B15: 0 | C15: No | D15: =IF(AND(B10=1,B11=1,B12=1,B13=1,B14=1),"Yes","") | E15: No | F15: No | G15: =IF(F15="Yes",1-B15,B15) | H15: =IF(E15="Yes","",COUNTIFS($E$2:E15,"No")) | I15: =IF(H15="","",IF(H15<=128,"address",IF(H15<=600,"data1",IF(H15<=1264,"zero-run1",IF(H15<=1648,"data2",IF(H15<=2176,"zero-run2",IF(H15<=2192,"FCS","trailing"))))))) | J15: =IFERROR(IF(AND(H15<>"",H15>=129,H15<=2176),INDEX(Fields!$B$2:$B$206,MATCH(H15-129,Fields!$D$2:$D$206,1)),""),"") | K15: =IFERROR(IF(AND(H15<>"",H15>=129,H15<=2176),INDEX(Fields!$C$2:$C$206,MATCH(H15-129,Fields!$D$2:$D$206,1)),""),"") | L15: =IFERROR(IF(AND(H15<>"",H15>=129,H15<=2176),INDEX(Fields!$J$2:$J$206,MATCH(H15-129,Fields!$D$2:$D$206,1)),""),"") | M15: =IFERROR(IF(AND(H15<>"",H15>=129,H15<=2176),INDEX(Fields!$K$2:$K$206,MATCH(H15-129,Fields!$D$2:$D$206,1)),""),"")
A16: 14 | B16: 0 | C16: No | D16: =IF(AND(B11=1,B12=1,B13=1,B14=1,B15=1),"Yes","") | E16: No | F16: No | G16: =IF(F16="Yes",1-B16,B16) | H16: =IF(E16="Yes","",COUNTIFS($E$2:E16,"No")) | I16: =IF(H16="","",IF(H16<=128,"address",IF(H16<=600,"data1",IF(H16<=1264,"zero-run1",IF(H16<=1648,"data2",IF(H16<=2176,"zero-run2",IF(H16<=2192,"FCS","trailing"))))))) | J16: =IFERROR(IF(AND(H16<>"",H16>=129,H16<=2176),INDEX(Fields!$B$2:$B$206,MATCH(H16-129,Fields!$D$2:$D$206,1)),""),"") | K16: =IFERROR(IF(AND(H16<>"",H16>=129,H16<=2176),INDEX(Fields!$C$2:$C$206,MATCH(H16-129,Fields!$D$2:$D$206,1)),""),"") | L16: =IFERROR(IF(AND(H16<>"",H16>=129,H16<=2176),INDEX(Fields!$J$2:$J$206,MATCH(H16-129,Fields!$D$2:$D$206,1)),""),"") | M16: =IFERROR(IF(AND(H16<>"",H16>=129,H16<=2176),INDEX(Fields!$K$2:$K$206,MATCH(H16-129,Fields!$D$2:$D$206,1)),""),"")
A17: 15 | B17: 1 | C17: No | D17: =IF(AND(B12=1,B13=1,B14=1,B15=1,B16=1),"Yes","") | E17: No | F17: No | G17: =IF(F17="Yes",1-B17,B17) | H17: =IF(E17="Yes","",COUNTIFS($E$2:E17,"No")) | I17: =IF(H17="","",IF(H17<=128,"address",IF(H17<=600,"data1",IF(H17<=1264,"zero-run1",IF(H17<=1648,"data2",IF(H17<=2176,"zero-run2",IF(H17<=2192,"FCS","trailing"))))))) | J17: =IFERROR(IF(AND(H17<>"",H17>=129,H17<=2176),INDEX(Fields!$B$2:$B$206,MATCH(H17-129,Fields!$D$2:$D$206,1)),""),"") | K17: =IFERROR(IF(AND(H17<>"",H17>=129,H17<=2176),INDEX(Fields!$C$2:$C$206,MATCH(H17-129,Fields!$D$2:$D$206,1)),""),"") | L17: =IFERROR(IF(AND(H17<>"",H17>=129,H17<=2176),INDEX(Fields!$J$2:$J$206,MATCH(H17-129,Fields!$D$2:$D$206,1)),""),"") | M17: =IFERROR(IF(AND(H17<>"",H17>=129,H17<=2176),INDEX(Fields!$K$2:$K$206,MATCH(H17-129,Fields!$D$2:$D$206,1)),""),"")
A18: 16 | B18: 0 | C18: No | D18: =IF(AND(B13=1,B14=1,B15=1,B16=1,B17=1),"Yes","") | E18: No | F18: No | G18: =IF(F18="Yes",1-B18,B18) | H18: =IF(E18="Yes","",COUNTIFS($E$2:E18,"No")) | I18: =IF(H18="","",IF(H18<=128,"address",IF(H18<=600,"data1",IF(H18<=1264,"zero-run1",IF(H18<=1648,"data2",IF(H18<=2176,"zero-run2",IF(H18<=2192,"FCS","trailing"))))))) | J18: =IFERROR(IF(AND(H18<>"",H18>=129,H18<=2176),INDEX(Fields!$B$2:$B$206,MATCH(H18-129,Fields!$D$2:$D$206,1)),""),"") | K18: =IFERROR(IF(AND(H18<>"",H18>=129,H18<=2176),INDEX(Fields!$C$2:$C$206,MATCH(H18-129,Fields!$D$2:$D$206,1)),""),"") | L18: =IFERROR(IF(AND(H18<>"",H18>=129,H18<=2176),INDEX(Fields!$J$2:$J$206,MATCH(H18-129,Fields!$D$2:$D$206,1)),""),"") | M18: =IFERROR(IF(AND(H18<>"",H18>=129,H18<=2176),INDEX(Fields!$K$2:$K$206,MATCH(H18-129,Fields!$D$2:$D$206,1)),""),"")
... A2241: 2239 | B2241: 1 | C2241: No | D2241: =IF(AND(B2236=1,B2237=1,B2238=1,B2239=1,B2240=1),"Yes","") | E2241: No | F2241: No | G2241: =IF(F2241="Yes",1-B2241,B2241) | H2241: =IF(E2241="Yes","",COUNTIFS($E$2:E2241,"No")) | I2241: =IF(H2241="","",IF(H2241<=128,"address",IF(H2241<=600,"data1",IF(H2241<=1264,"zero-run1",IF(H2241<=1648,"data2",IF(H2241<=2176,"zero-run2",IF(H2241<=2192,"FCS","trailing"))))))) | J2241: =IFERROR(IF(AND(H2241<>"",H2241>=129,H2241<=2176),INDEX(Fields!$B$2:$B$206,MATCH(H2241-129,Fields!$D$2:$D$206,1)),""),"") | K2241: =IFERROR(IF(AND(H2241<>"",H2241>=129,H2241<=2176),INDEX(Fields!$C$2:$C$206,MATCH(H2241-129,Fields!$D$2:$D$206,1)),""),"") | L2241: =IFERROR(IF(AND(H2241<>"",H2241>=129,H2241<=2176),INDEX(Fields!$J$2:$J$206,MATCH(H2241-129,Fields!$D$2:$D$206,1)),""),"") | M2241: =IFERROR(IF(AND(H2241<>"",H2241>=129,H2241<=2176),INDEX(Fields!$K$2:$K$206,MATCH(H2241-129,Fields!$D$2:$D$206,1)),""),"")

Sheet _DestuffedBits
A1: Position | B1: SourceRawBitIndex | C1: DestuffedBitValue | D1: Subsystem | E1: ItemName
A2: 1 | B2: =IFERROR(INDEX(RawBits!$A:$A,MATCH($A2,RawBits!$H:$H,0)),"?") | C2: =IFERROR(INDEX(RawBits!$G:$G,MATCH($A2,RawBits!$H:$H,0)),"") | D2: =IFERROR(IF(AND(A2>=129,A2<=2176),INDEX(Fields!$B$2:$B$206,MATCH(A2-129,Fields!$D$2:$D$206,1)),""),"") | E2: =IFERROR(IF(AND(A2>=129,A2<=2176),INDEX(Fields!$C$2:$C$206,MATCH(A2-129,Fields!$D$2:$D$206,1)),""),"")
A3: 2 | B3: =IFERROR(INDEX(RawBits!$A:$A,MATCH($A3,RawBits!$H:$H,0)),"?") | C3: =IFERROR(INDEX(RawBits!$G:$G,MATCH($A3,RawBits!$H:$H,0)),"") | D3: =IFERROR(IF(AND(A3>=129,A3<=2176),INDEX(Fields!$B$2:$B$206,MATCH(A3-129,Fields!$D$2:$D$206,1)),""),"") | E3: =IFERROR(IF(AND(A3>=129,A3<=2176),INDEX(Fields!$C$2:$C$206,MATCH(A3-129,Fields!$D$2:$D$206,1)),""),"")
A4: 3 | B4: =IFERROR(INDEX(RawBits!$A:$A,MATCH($A4,RawBits!$H:$H,0)),"?") | C4: =IFERROR(INDEX(RawBits!$G:$G,MATCH($A4,RawBits!$H:$H,0)),"") | D4: =IFERROR(IF(AND(A4>=129,A4<=2176),INDEX(Fields!$B$2:$B$206,MATCH(A4-129,Fields!$D$2:$D$206,1)),""),"") | E4: =IFERROR(IF(AND(A4>=129,A4<=2176),INDEX(Fields!$C$2:$C$206,MATCH(A4-129,Fields!$D$2:$D$206,1)),""),"")
A5: 4 | B5: =IFERROR(INDEX(RawBits!$A:$A,MATCH($A5,RawBits!$H:$H,0)),"?") | C5: =IFERROR(INDEX(RawBits!$G:$G,MATCH($A5,RawBits!$H:$H,0)),"") | D5: =IFERROR(IF(AND(A5>=129,A5<=2176),INDEX(Fields!$B$2:$B$206,MATCH(A5-129,Fields!$D$2:$D$206,1)),""),"") | E5: =IFERROR(IF(AND(A5>=129,A5<=2176),INDEX(Fields!$C$2:$C$206,MATCH(A5-129,Fields!$D$2:$D$206,1)),""),"")
A6: 5 | B6: =IFERROR(INDEX(RawBits!$A:$A,MATCH($A6,RawBits!$H:$H,0)),"?") | C6: =IFERROR(INDEX(RawBits!$G:$G,MATCH($A6,RawBits!$H:$H,0)),"") | D6: =IFERROR(IF(AND(A6>=129,A6<=2176),INDEX(Fields!$B$2:$B$206,MATCH(A6-129,Fields!$D$2:$D$206,1)),""),"") | E6: =IFERROR(IF(AND(A6>=129,A6<=2176),INDEX(Fields!$C$2:$C$206,MATCH(A6-129,Fields!$D$2:$D$206,1)),""),"")
A7: 6 | B7: =IFERROR(INDEX(RawBits!$A:$A,MATCH($A7,RawBits!$H:$H,0)),"?") | C7: =IFERROR(INDEX(RawBits!$G:$G,MATCH($A7,RawBits!$H:$H,0)),"") | D7: =IFERROR(IF(AND(A7>=129,A7<=2176),INDEX(Fields!$B$2:$B$206,MATCH(A7-129,Fields!$D$2:$D$206,1)),""),"") | E7: =IFERROR(IF(AND(A7>=129,A7<=2176),INDEX(Fields!$C$2:$C$206,MATCH(A7-129,Fields!$D$2:$D$206,1)),""),"")
A8: 7 | B8: =IFERROR(INDEX(RawBits!$A:$A,MATCH($A8,RawBits!$H:$H,0)),"?") | C8: =IFERROR(INDEX(RawBits!$G:$G,MATCH($A8,RawBits!$H:$H,0)),"") | D8: =IFERROR(IF(AND(A8>=129,A8<=2176),INDEX(Fields!$B$2:$B$206,MATCH(A8-129,Fields!$D$2:$D$206,1)),""),"") | E8: =IFERROR(IF(AND(A8>=129,A8<=2176),INDEX(Fields!$C$2:$C$206,MATCH(A8-129,Fields!$D$2:$D$206,1)),""),"")
A9: 8 | B9: =IFERROR(INDEX(RawBits!$A:$A,MATCH($A9,RawBits!$H:$H,0)),"?") | C9: =IFERROR(INDEX(RawBits!$G:$G,MATCH($A9,RawBits!$H:$H,0)),"") | D9: =IFERROR(IF(AND(A9>=129,A9<=2176),INDEX(Fields!$B$2:$B$206,MATCH(A9-129,Fields!$D$2:$D$206,1)),""),"") | E9: =IFERROR(IF(AND(A9>=129,A9<=2176),INDEX(Fields!$C$2:$C$206,MATCH(A9-129,Fields!$D$2:$D$206,1)),""),"")
A10: 9 | B10: =IFERROR(INDEX(RawBits!$A:$A,MATCH($A10,RawBits!$H:$H,0)),"?") | C10: =IFERROR(INDEX(RawBits!$G:$G,MATCH($A10,RawBits!$H:$H,0)),"") | D10: =IFERROR(IF(AND(A10>=129,A10<=2176),INDEX(Fields!$B$2:$B$206,MATCH(A10-129,Fields!$D$2:$D$206,1)),""),"") | E10: =IFERROR(IF(AND(A10>=129,A10<=2176),INDEX(Fields!$C$2:$C$206,MATCH(A10-129,Fields!$D$2:$D$206,1)),""),"")
A11: 10 | B11: =IFERROR(INDEX(RawBits!$A:$A,MATCH($A11,RawBits!$H:$H,0)),"?") | C11: =IFERROR(INDEX(RawBits!$G:$G,MATCH($A11,RawBits!$H:$H,0)),"") | D11: =IFERROR(IF(AND(A11>=129,A11<=2176),INDEX(Fields!$B$2:$B$206,MATCH(A11-129,Fields!$D$2:$D$206,1)),""),"") | E11: =IFERROR(IF(AND(A11>=129,A11<=2176),INDEX(Fields!$C$2:$C$206,MATCH(A11-129,Fields!$D$2:$D$206,1)),""),"")
A12: 11 | B12: =IFERROR(INDEX(RawBits!$A:$A,MATCH($A12,RawBits!$H:$H,0)),"?") | C12: =IFERROR(INDEX(RawBits!$G:$G,MATCH($A12,RawBits!$H:$H,0)),"") | D12: =IFERROR(IF(AND(A12>=129,A12<=2176),INDEX(Fields!$B$2:$B$206,MATCH(A12-129,Fields!$D$2:$D$206,1)),""),"") | E12: =IFERROR(IF(AND(A12>=129,A12<=2176),INDEX(Fields!$C$2:$C$206,MATCH(A12-129,Fields!$D$2:$D$206,1)),""),"")
A13: 12 | B13: =IFERROR(INDEX(RawBits!$A:$A,MATCH($A13,RawBits!$H:$H,0)),"?") | C13: =IFERROR(INDEX(RawBits!$G:$G,MATCH($A13,RawBits!$H:$H,0)),"") | D13: =IFERROR(IF(AND(A13>=129,A13<=2176),INDEX(Fields!$B$2:$B$206,MATCH(A13-129,Fields!$D$2:$D$206,1)),""),"") | E13: =IFERROR(IF(AND(A13>=129,A13<=2176),INDEX(Fields!$C$2:$C$206,MATCH(A13-129,Fields!$D$2:$D$206,1)),""),"")
... A2193: 2192 | B2193: =IFERROR(INDEX(RawBits!$A:$A,MATCH($A2193,RawBits!$H:$H,0)),"?") | C2193: =IFERROR(INDEX(RawBits!$G:$G,MATCH($A2193,RawBits!$H:$H,0)),"") | D2193: =IFERROR(IF(AND(A2193>=129,A2193<=2176),INDEX(Fields!$B$2:$B$206,MATCH(A2193-129,Fields!$D$2:$D$206,1)),""),"") | E2193: =IFERROR(IF(AND(A2193>=129,A2193<=2176),INDEX(Fields!$C$2:$C$206,MATCH(A2193-129,Fields!$D$2:$D$206,1)),""),"")

Sheet Beacon Decode
A1: Subsystem | B1: ItemName | C1: OffsetBit | D1: BitLen | E1: Bits | F1: ReadableValue | G1: LookupTable
A2: HEADER | B2: Dest Address | C2: 0 | D2: 56 | E2: =_DestuffedBits!C2&_DestuffedBits!C3&_DestuffedBits!C4&_DestuffedBits!C5&_DestuffedBits!C6&_DestuffedBits!C7&_DestuffedBits!C8&_DestuffedBits!C9&_DestuffedBits!C10&_DestuffedBits!C11&_DestuffedBits!C12&_DestuffedBits!C13&_DestuffedBits!C14&_DestuffedBits!C15&_DestuffedBits!C16&_DestuffedBits!C17&_DestuffedBits!C18&_DestuffedBits!C19&_DestuffedBits!C20&_DestuffedBits!C21&_DestuffedBits!C22&_DestuffedBits!C23&_DestuffedBits!C24&_DestuffedBits!C25&_DestuffedBits!C26&_DestuffedBits!C27&_DestuffedBits!C28&_DestuffedBits!C29&_DestuffedBits!C30&_DestuffedBits!C31&_DestuffedBits!C32&_DestuffedBits!C33&_DestuffedBits!C34&_DestuffedBits!C35&_DestuffedBits!C36&_DestuffedBits!C37&_DestuffedBits!C38&_DestuffedBits!C39&_DestuffedBits!C40&_DestuffedBits!C41&_DestuffedBits!C42&_DestuffedBits!C43&_DestuffedBits!C44&_DestuffedBits!C45&_DestuffedBits!C46&_DestuffedBits!C47&_DestuffedBits!C48&_DestuffedBits!C49&_DestuffedBits!C50&_DestuffedBits!C51&_DestuffedBits!C52&_DestuffedBits!C53&_DestuffedBits!C54&_DestuffedBits!C55&_DestuffedBits!C56&_DestuffedBits!C57 | F2: ="'"&IF(AND(INT((_DestuffedBits!C2*1+_DestuffedBits!C3*2+_DestuffedBits!C4*4+_DestuffedBits!C5*8+_DestuffedBits!C6*16+_DestuffedBits!C7*32+_DestuffedBits!C8*64+_DestuffedBits!C9*128)/2)>=32,INT((_DestuffedBits!C2*1+_DestuffedBits!C3*2+_DestuffedBits!C4*4+_DestuffedBits!C5*8+_DestuffedBits!C6*16+_DestuffedBits!C7*32+_DestuffedBits!C8*64+_DestuffedBits!C9*128)/2)<127),CHAR(INT((_DestuffedBits!C2*1+_DestuffedBits!C3*2+_DestuffedBits!C4*4+_DestuffedBits!C5*8+_DestuffedBits!C6*16+_DestuffedBits!C7*32+_DestuffedBits!C8*64+_DestuffedBits!C9*128)/2)),"?")&IF(AND(INT((_DestuffedBits!C10*1+_DestuffedBits!C11*2+_DestuffedBits!C12*4+_DestuffedBits!C13*8+_DestuffedBits!C14*16+_DestuffedBits!C15*32+_DestuffedBits!C16*64+_DestuffedBits!C17*128)/2)>=32,INT((_DestuffedBits!C10*1+_DestuffedBits!C11*2+_DestuffedBits!C12*4+_DestuffedBits!C13*8+_DestuffedBits!C14*16+_DestuffedBits!C15*32+_DestuffedBits!C16*64+_DestuffedBits!C17*128)/2)<127),CHAR(INT((_DestuffedBits!C10*1+_DestuffedBits!C11*2+_DestuffedBits!C12*4+_DestuffedBits!C13*8+_DestuffedBits!C14*16+_DestuffedBits!C15*32+_DestuffedBits!C16*64+_DestuffedBits!C17*128)/2)),"?")&IF(AND(INT((_DestuffedBits!C18*1+_DestuffedBits!C19*2+_DestuffedBits!C20*4+_DestuffedBits!C21*8+_DestuffedBits!C22*16+_DestuffedBits!C23*32+_DestuffedBits!C24*64+_DestuffedBits!C25*128)/2)>=32,INT((_DestuffedBits!C18*1+_DestuffedBits!C19*2+_DestuffedBits!C20*4+_DestuffedBits!C21*8+_DestuffedBits!C22*16+_DestuffedBits!C23*32+_DestuffedBits!C24*64+_DestuffedBits!C25*128)/2)<127),CHAR(INT((_DestuffedBits!C18*1+_DestuffedBits!C19*2+_DestuffedBits!C20*4+_DestuffedBits!C21*8+_DestuffedBits!C22*16+_DestuffedBits!C23*32+_DestuffedBits!C24*64+_DestuffedBits!C25*128)/2)),"?")&IF(AND(INT((_DestuffedBits!C26*1+_DestuffedBits!C27*2+_DestuffedBits!C28*4+_DestuffedBits!C29*8+_DestuffedBits!C30*16+_DestuffedBits!C31*32+_DestuffedBits!C32*64+_DestuffedBits!C33*128)/2)>=32,INT((_DestuffedBits!C26*1+_DestuffedBits!C27*2+_DestuffedBits!C28*4+_DestuffedBits!C29*8+_DestuffedBits!C30*16+_DestuffedBits!C31*32+_DestuffedBits!C32*64+_DestuffedBits!C33*128)/2)<127),CHAR(INT((_DestuffedBits!C26*1+_DestuffedBits!C27*2+_DestuffedBits!C28*4+_DestuffedBits!C29*8+_DestuffedBits!C30*16+_DestuffedBits!C31*32+_DestuffedBits!C32*64+_DestuffedBits!C33*128)/2)),"?")&IF(AND(INT((_DestuffedBits!C34*1+_DestuffedBits!C35*2+_DestuffedBits!C36*4+_DestuffedBits!C37*8+_DestuffedBits!C38*16+_DestuffedBits!C39*32+_DestuffedBits!C40*64+_DestuffedBits!C41*128)/2)>=32,INT((_DestuffedBits!C34*1+_DestuffedBits!C35*2+_DestuffedBits!C36*4+_DestuffedBits!C37*8+_DestuffedBits!C38*16+_DestuffedBits!C39*32+_DestuffedBits!C40*64+_DestuffedBits!C41*128)/2)<127),CHAR(INT((_DestuffedBits!C34*1+_DestuffedBits!C35*2+_DestuffedBits!C36*4+_DestuffedBits!C37*8+_DestuffedBits!C38*16+_DestuffedBits!C39*32+_DestuffedBits!C40*64+_DestuffedBits!C41*128)/2)),"?")&IF(AND(INT((_DestuffedBits!C42*1+_DestuffedBits!C43*2+_DestuffedBits!C44*4+_DestuffedBits!C45*8+_DestuffedBits!C46*16+_DestuffedBits!C47*32+_DestuffedBits!C48*64+_DestuffedBits!C49*128)/2)>=32,INT((_DestuffedBits!C42*1+_DestuffedBits!C43*2+_DestuffedBits!C44*4+_DestuffedBits!C45*8+_DestuffedBits!C46*16+_DestuffedBits!C47*32+_DestuffedBits!C48*64+_DestuffedBits!C49*128)/2)<127),CHAR(INT((_DestuffedBits!C42*1+_DestuffedBits!C43*2+_DestuffedBits!C44*4+_DestuffedBits!C45*8+_DestuffedBits!C46*16+_DestuffedBits!C47*32+_DestuffedBits!C48*64+_DestuffedBits!C49*128)/2)),"?")&"' (SSID byte=0x"&DEC2HEX(_DestuffedBits!C50*1+_DestuffedBits!C51*2+_DestuffedBits!C52*4+_DestuffedBits!C53*8+_DestuffedBits!C54*16+_DestuffedBits!C55*32+_DestuffedBits!C56*64+_DestuffedBits!C57*128,2)&")" | G2: expect 'BN0CU ' (>>1 of each byte, ground-test reference)
A3: HEADER | B3: Src Address | C3: 56 | D3: 56 | E3: =_DestuffedBits!C58&_DestuffedBits!C59&_DestuffedBits!C60&_DestuffedBits!C61&_DestuffedBits!C62&_DestuffedBits!C63&_DestuffedBits!C64&_DestuffedBits!C65&_DestuffedBits!C66&_DestuffedBits!C67&_DestuffedBits!C68&_DestuffedBits!C69&_DestuffedBits!C70&_DestuffedBits!C71&_DestuffedBits!C72&_DestuffedBits!C73&_DestuffedBits!C74&_DestuffedBits!C75&_DestuffedBits!C76&_DestuffedBits!C77&_DestuffedBits!C78&_DestuffedBits!C79&_DestuffedBits!C80&_DestuffedBits!C81&_DestuffedBits!C82&_DestuffedBits!C83&_DestuffedBits!C84&_DestuffedBits!C85&_DestuffedBits!C86&_DestuffedBits!C87&_DestuffedBits!C88&_DestuffedBits!C89&_DestuffedBits!C90&_DestuffedBits!C91&_DestuffedBits!C92&_DestuffedBits!C93&_DestuffedBits!C94&_DestuffedBits!C95&_DestuffedBits!C96&_DestuffedBits!C97&_DestuffedBits!C98&_DestuffedBits!C99&_DestuffedBits!C100&_DestuffedBits!C101&_DestuffedBits!C102&_DestuffedBits!C103&_DestuffedBits!C104&_DestuffedBits!C105&_DestuffedBits!C106&_DestuffedBits!C107&_DestuffedBits!C108&_DestuffedBits!C109&_DestuffedBits!C110&_DestuffedBits!C111&_DestuffedBits!C112&_DestuffedBits!C113 | F3: ="'"&IF(AND(INT((_DestuffedBits!C58*1+_DestuffedBits!C59*2+_DestuffedBits!C60*4+_DestuffedBits!C61*8+_DestuffedBits!C62*16+_DestuffedBits!C63*32+_DestuffedBits!C64*64+_DestuffedBits!C65*128)/2)>=32,INT((_DestuffedBits!C58*1+_DestuffedBits!C59*2+_DestuffedBits!C60*4+_DestuffedBits!C61*8+_DestuffedBits!C62*16+_DestuffedBits!C63*32+_DestuffedBits!C64*64+_DestuffedBits!C65*128)/2)<127),CHAR(INT((_DestuffedBits!C58*1+_DestuffedBits!C59*2+_DestuffedBits!C60*4+_DestuffedBits!C61*8+_DestuffedBits!C62*16+_DestuffedBits!C63*32+_DestuffedBits!C64*64+_DestuffedBits!C65*128)/2)),"?")&IF(AND(INT((_DestuffedBits!C66*1+_DestuffedBits!C67*2+_DestuffedBits!C68*4+_DestuffedBits!C69*8+_DestuffedBits!C70*16+_DestuffedBits!C71*32+_DestuffedBits!C72*64+_DestuffedBits!C73*128)/2)>=32,INT((_DestuffedBits!C66*1+_DestuffedBits!C67*2+_DestuffedBits!C68*4+_DestuffedBits!C69*8+_DestuffedBits!C70*16+_DestuffedBits!C71*32+_DestuffedBits!C72*64+_DestuffedBits!C73*128)/2)<127),CHAR(INT((_DestuffedBits!C66*1+_DestuffedBits!C67*2+_DestuffedBits!C68*4+_DestuffedBits!C69*8+_DestuffedBits!C70*16+_DestuffedBits!C71*32+_DestuffedBits!C72*64+_DestuffedBits!C73*128)/2)),"?")&IF(AND(INT((_DestuffedBits!C74*1+_DestuffedBits!C75*2+_DestuffedBits!C76*4+_DestuffedBits!C77*8+_DestuffedBits!C78*16+_DestuffedBits!C79*32+_DestuffedBits!C80*64+_DestuffedBits!C81*128)/2)>=32,INT((_DestuffedBits!C74*1+_DestuffedBits!C75*2+_DestuffedBits!C76*4+_DestuffedBits!C77*8+_DestuffedBits!C78*16+_DestuffedBits!C79*32+_DestuffedBits!C80*64+_DestuffedBits!C81*128)/2)<127),CHAR(INT((_DestuffedBits!C74*1+_DestuffedBits!C75*2+_DestuffedBits!C76*4+_DestuffedBits!C77*8+_DestuffedBits!C78*16+_DestuffedBits!C79*32+_DestuffedBits!C80*64+_DestuffedBits!C81*128)/2)),"?")&IF(AND(INT((_DestuffedBits!C82*1+_DestuffedBits!C83*2+_DestuffedBits!C84*4+_DestuffedBits!C85*8+_DestuffedBits!C86*16+_DestuffedBits!C87*32+_DestuffedBits!C88*64+_DestuffedBits!C89*128)/2)>=32,INT((_DestuffedBits!C82*1+_DestuffedBits!C83*2+_DestuffedBits!C84*4+_DestuffedBits!C85*8+_DestuffedBits!C86*16+_DestuffedBits!C87*32+_DestuffedBits!C88*64+_DestuffedBits!C89*128)/2)<127),CHAR(INT((_DestuffedBits!C82*1+_DestuffedBits!C83*2+_DestuffedBits!C84*4+_DestuffedBits!C85*8+_DestuffedBits!C86*16+_DestuffedBits!C87*32+_DestuffedBits!C88*64+_DestuffedBits!C89*128)/2)),"?")&IF(AND(INT((_DestuffedBits!C90*1+_DestuffedBits!C91*2+_DestuffedBits!C92*4+_DestuffedBits!C93*8+_DestuffedBits!C94*16+_DestuffedBits!C95*32+_DestuffedBits!C96*64+_DestuffedBits!C97*128)/2)>=32,INT((_DestuffedBits!C90*1+_DestuffedBits!C91*2+_DestuffedBits!C92*4+_DestuffedBits!C93*8+_DestuffedBits!C94*16+_DestuffedBits!C95*32+_DestuffedBits!C96*64+_DestuffedBits!C97*128)/2)<127),CHAR(INT((_DestuffedBits!C90*1+_DestuffedBits!C91*2+_DestuffedBits!C92*4+_DestuffedBits!C93*8+_DestuffedBits!C94*16+_DestuffedBits!C95*32+_DestuffedBits!C96*64+_DestuffedBits!C97*128)/2)),"?")&IF(AND(INT((_DestuffedBits!C98*1+_DestuffedBits!C99*2+_DestuffedBits!C100*4+_DestuffedBits!C101*8+_DestuffedBits!C102*16+_DestuffedBits!C103*32+_DestuffedBits!C104*64+_DestuffedBits!C105*128)/2)>=32,INT((_DestuffedBits!C98*1+_DestuffedBits!C99*2+_DestuffedBits!C100*4+_DestuffedBits!C101*8+_DestuffedBits!C102*16+_DestuffedBits!C103*32+_DestuffedBits!C104*64+_DestuffedBits!C105*128)/2)<127),CHAR(INT((_DestuffedBits!C98*1+_DestuffedBits!C99*2+_DestuffedBits!C100*4+_DestuffedBits!C101*8+_DestuffedBits!C102*16+_DestuffedBits!C103*32+_DestuffedBits!C104*64+_DestuffedBits!C105*128)/2)),"?")&"' (SSID byte=0x"&DEC2HEX(_DestuffedBits!C106*1+_DestuffedBits!C107*2+_DestuffedBits!C108*4+_DestuffedBits!C109*8+_DestuffedBits!C110*16+_DestuffedBits!C111*32+_DestuffedBits!C112*64+_DestuffedBits!C113*128,2)&")" | G3: expect 'BN0SCX' (>>1 of each byte, ground-test reference)
A4: HEADER | B4: Control | C4: 112 | D4: 8 | E4: =_DestuffedBits!C114&_DestuffedBits!C115&_DestuffedBits!C116&_DestuffedBits!C117&_DestuffedBits!C118&_DestuffedBits!C119&_DestuffedBits!C120&_DestuffedBits!C121 | F4: ="0x"&DEC2HEX(_DestuffedBits!C114*1+_DestuffedBits!C115*2+_DestuffedBits!C116*4+_DestuffedBits!C117*8+_DestuffedBits!C118*16+_DestuffedBits!C119*32+_DestuffedBits!C120*64+_DestuffedBits!C121*128,2) | G4: expect 0x03 (UI frame)
A5: HEADER | B5: PID | C5: 120 | D5: 8 | E5: =_DestuffedBits!C122&_DestuffedBits!C123&_DestuffedBits!C124&_DestuffedBits!C125&_DestuffedBits!C126&_DestuffedBits!C127&_DestuffedBits!C128&_DestuffedBits!C129 | F5: ="0x"&DEC2HEX(_DestuffedBits!C122*1+_DestuffedBits!C123*2+_DestuffedBits!C124*4+_DestuffedBits!C125*8+_DestuffedBits!C126*16+_DestuffedBits!C127*32+_DestuffedBits!C128*64+_DestuffedBits!C129*128,2) | G5: expect 0xF0 (no layer-3)
A6: FSW | B6: APID | C6: 0 | D6: 8 | E6: =_DestuffedBits!C130&_DestuffedBits!C131&_DestuffedBits!C132&_DestuffedBits!C133&_DestuffedBits!C134&_DestuffedBits!C135&_DestuffedBits!C136&_DestuffedBits!C137 | F6: =Fields!J2 | G6: =Fields!K2
A7: FSW | B7: First boot | C7: 8 | D7: 1 | E7: =_DestuffedBits!C138 | F7: =Fields!J3 | G7: =Fields!K3
A8: FSW | B8: Going to ADCS commission | C8: 9 | D8: 1 | E8: =_DestuffedBits!C139 | F8: =Fields!J4 | G8: =Fields!K4
A9: FSW | B9: adcs_commissioned | C9: 10 | D9: 1 | E9: =_DestuffedBits!C140 | F9: =Fields!J5 | G9: =Fields!K5
A10: FSW | B10: MAG | C10: 11 | D10: 1 | E10: =_DestuffedBits!C141 | F10: =Fields!J6 | G10: =Fields!K6
A11: FSW | B11: SP1 | C11: 12 | D11: 1 | E11: =_DestuffedBits!C142 | F11: =Fields!J7 | G11: =Fields!K7
A12: FSW | B12: SP2 | C12: 13 | D12: 1 | E12: =_DestuffedBits!C143 | F12: =Fields!J8 | G12: =Fields!K8
A13: FSW | B13: VHF | C13: 14 | D13: 1 | E13: =_DestuffedBits!C144 | F13: =Fields!J9 | G13: =Fields!K9
A14: FSW | B14: UHF | C14: 15 | D14: 1 | E14: =_DestuffedBits!C145 | F14: =Fields!J10 | G14: =Fields!K10
A15: FSW | B15: sys_state - factory reset | C15: 16 | D15: 1 | E15: =_DestuffedBits!C146 | F15: =Fields!J11 | G15: =Fields!K11
A16: FSW | B16: sys_state - reset | C16: 17 | D16: 1 | E16: =_DestuffedBits!C147 | F16: =Fields!J12 | G16: =Fields!K12
A17: FSW | B17: Main SD select | C17: 18 | D17: 1 | E17: =_DestuffedBits!C148 | F17: =Fields!J13 | G17: =Fields!K13
A18: FSW | B18: Nominal | C18: 19 | D18: 1 | E18: =_DestuffedBits!C149 | F18: =Fields!J14 | G18: =Fields!K14
A19: FSW | B19: (reserved) | C19: 20 | D19: 4 | E19: =_DestuffedBits!C150&_DestuffedBits!C151&_DestuffedBits!C152&_DestuffedBits!C153 | F19: =Fields!J15 | G19: =Fields!K15
A20: FSW | B20: OBC Time | C20: 24 | D20: 32 | E20: =_DestuffedBits!C154&_DestuffedBits!C155&_DestuffedBits!C156&_DestuffedBits!C157&_DestuffedBits!C158&_DestuffedBits!C159&_DestuffedBits!C160&_DestuffedBits!C161&_DestuffedBits!C162&_DestuffedBits!C163&_DestuffedBits!C164&_DestuffedBits!C165&_DestuffedBits!C166&_DestuffedBits!C167&_DestuffedBits!C168&_DestuffedBits!C169&_DestuffedBits!C170&_DestuffedBits!C171&_DestuffedBits!C172&_DestuffedBits!C173&_DestuffedBits!C174&_DestuffedBits!C175&_DestuffedBits!C176&_DestuffedBits!C177&_DestuffedBits!C178&_DestuffedBits!C179&_DestuffedBits!C180&_DestuffedBits!C181&_DestuffedBits!C182&_DestuffedBits!C183&_DestuffedBits!C184&_DestuffedBits!C185 | F20: =Fields!J16 | G20: =Fields!K16
A21: FSW | B21: Current Mode | C21: 56 | D21: 8 | E21: =_DestuffedBits!C186&_DestuffedBits!C187&_DestuffedBits!C188&_DestuffedBits!C189&_DestuffedBits!C190&_DestuffedBits!C191&_DestuffedBits!C192&_DestuffedBits!C193 | F21: =Fields!J17 | G21: =Fields!K17
A22: FSW | B22: EPS onoff state | C22: 64 | D22: 1 | E22: =_DestuffedBits!C194 | F22: =Fields!J18 | G22: =Fields!K18
A23: FSW | B23: ADCS onoff state | C23: 65 | D23: 1 | E23: =_DestuffedBits!C195 | F23: =Fields!J19 | G23: =Fields!K19
A24: FSW | B24: UHF onoff state | C24: 66 | D24: 1 | E24: =_DestuffedBits!C196 | F24: =Fields!J20 | G24: =Fields!K20
A25: FSW | B25: Xband onoff state | C25: 67 | D25: 1 | E25: =_DestuffedBits!C197 | F25: =Fields!J21 | G25: =Fields!K21
A26: FSW | B26: CIP onoff state | C26: 68 | D26: 1 | E26: =_DestuffedBits!C198 | F26: =Fields!J22 | G26: =Fields!K22
A27: FSW | B27: HyperSCAN onoff state | C27: 69 | D27: 1 | E27: =_DestuffedBits!C199 | F27: =Fields!J23 | G27: =Fields!K23
A28: FSW | B28: SEUV onoff state | C28: 70 | D28: 1 | E28: =_DestuffedBits!C200 | F28: =Fields!J24 | G28: =Fields!K24
A29: FSW | B29: APRS onoff state | C29: 71 | D29: 1 | E29: =_DestuffedBits!C201 | F29: =Fields!J25 | G29: =Fields!K25
A30: FSW | B30: FSW Reboot Count | C30: 72 | D30: 16 | E30: =_DestuffedBits!C202&_DestuffedBits!C203&_DestuffedBits!C204&_DestuffedBits!C205&_DestuffedBits!C206&_DestuffedBits!C207&_DestuffedBits!C208&_DestuffedBits!C209&_DestuffedBits!C210&_DestuffedBits!C211&_DestuffedBits!C212&_DestuffedBits!C213&_DestuffedBits!C214&_DestuffedBits!C215&_DestuffedBits!C216&_DestuffedBits!C217 | F30: =Fields!J26 | G30: =Fields!K26
A31: FSW | B31: CMD Accept Count | C31: 88 | D31: 16 | E31: =_DestuffedBits!C218&_DestuffedBits!C219&_DestuffedBits!C220&_DestuffedBits!C221&_DestuffedBits!C222&_DestuffedBits!C223&_DestuffedBits!C224&_DestuffedBits!C225&_DestuffedBits!C226&_DestuffedBits!C227&_DestuffedBits!C228&_DestuffedBits!C229&_DestuffedBits!C230&_DestuffedBits!C231&_DestuffedBits!C232&_DestuffedBits!C233 | F31: =Fields!J27 | G31: =Fields!K27
A32: FSW | B32: CMD Reject Count | C32: 104 | D32: 16 | E32: =_DestuffedBits!C234&_DestuffedBits!C235&_DestuffedBits!C236&_DestuffedBits!C237&_DestuffedBits!C238&_DestuffedBits!C239&_DestuffedBits!C240&_DestuffedBits!C241&_DestuffedBits!C242&_DestuffedBits!C243&_DestuffedBits!C244&_DestuffedBits!C245&_DestuffedBits!C246&_DestuffedBits!C247&_DestuffedBits!C248&_DestuffedBits!C249 | F32: =Fields!J28 | G32: =Fields!K28
A33: FSW | B33: Last packet send | C33: 120 | D33: 32 | E33: =_DestuffedBits!C250&_DestuffedBits!C251&_DestuffedBits!C252&_DestuffedBits!C253&_DestuffedBits!C254&_DestuffedBits!C255&_DestuffedBits!C256&_DestuffedBits!C257&_DestuffedBits!C258&_DestuffedBits!C259&_DestuffedBits!C260&_DestuffedBits!C261&_DestuffedBits!C262&_DestuffedBits!C263&_DestuffedBits!C264&_DestuffedBits!C265&_DestuffedBits!C266&_DestuffedBits!C267&_DestuffedBits!C268&_DestuffedBits!C269&_DestuffedBits!C270&_DestuffedBits!C271&_DestuffedBits!C272&_DestuffedBits!C273&_DestuffedBits!C274&_DestuffedBits!C275&_DestuffedBits!C276&_DestuffedBits!C277&_DestuffedBits!C278&_DestuffedBits!C279&_DestuffedBits!C280&_DestuffedBits!C281 | F33: =Fields!J29 | G33: =Fields!K29
A34: FSW | B34: Last packet send time | C34: 152 | D34: 32 | E34: =_DestuffedBits!C282&_DestuffedBits!C283&_DestuffedBits!C284&_DestuffedBits!C285&_DestuffedBits!C286&_DestuffedBits!C287&_DestuffedBits!C288&_DestuffedBits!C289&_DestuffedBits!C290&_DestuffedBits!C291&_DestuffedBits!C292&_DestuffedBits!C293&_DestuffedBits!C294&_DestuffedBits!C295&_DestuffedBits!C296&_DestuffedBits!C297&_DestuffedBits!C298&_DestuffedBits!C299&_DestuffedBits!C300&_DestuffedBits!C301&_DestuffedBits!C302&_DestuffedBits!C303&_DestuffedBits!C304&_DestuffedBits!C305&_DestuffedBits!C306&_DestuffedBits!C307&_DestuffedBits!C308&_DestuffedBits!C309&_DestuffedBits!C310&_DestuffedBits!C311&_DestuffedBits!C312&_DestuffedBits!C313 | F34: =Fields!J30 | G34: =Fields!K30
A35: FSW | B35: Last Accept CMD Time | C35: 184 | D35: 32 | E35: =_DestuffedBits!C314&_DestuffedBits!C315&_DestuffedBits!C316&_DestuffedBits!C317&_DestuffedBits!C318&_DestuffedBits!C319&_DestuffedBits!C320&_DestuffedBits!C321&_DestuffedBits!C322&_DestuffedBits!C323&_DestuffedBits!C324&_DestuffedBits!C325&_DestuffedBits!C326&_DestuffedBits!C327&_DestuffedBits!C328&_DestuffedBits!C329&_DestuffedBits!C330&_DestuffedBits!C331&_DestuffedBits!C332&_DestuffedBits!C333&_DestuffedBits!C334&_DestuffedBits!C335&_DestuffedBits!C336&_DestuffedBits!C337&_DestuffedBits!C338&_DestuffedBits!C339&_DestuffedBits!C340&_DestuffedBits!C341&_DestuffedBits!C342&_DestuffedBits!C343&_DestuffedBits!C344&_DestuffedBits!C345 | F35: =Fields!J31 | G35: =Fields!K31
A36: FSW | B36: Last Accept CMD Type OPCODE | C36: 216 | D36: 4 | E36: =_DestuffedBits!C346&_DestuffedBits!C347&_DestuffedBits!C348&_DestuffedBits!C349 | F36: =Fields!J32 | G36: =Fields!K32
A37: FSW | B37: Last Accept CMD Type APID | C37: 220 | D37: 4 | E37: =_DestuffedBits!C350&_DestuffedBits!C351&_DestuffedBits!C352&_DestuffedBits!C353 | F37: =Fields!J33 | G37: =Fields!K33
A38: FSW | B38: FSW static data addr | C38: 224 | D38: 32 | E38: =_DestuffedBits!C354&_DestuffedBits!C355&_DestuffedBits!C356&_DestuffedBits!C357&_DestuffedBits!C358&_DestuffedBits!C359&_DestuffedBits!C360&_DestuffedBits!C361&_DestuffedBits!C362&_DestuffedBits!C363&_DestuffedBits!C364&_DestuffedBits!C365&_DestuffedBits!C366&_DestuffedBits!C367&_DestuffedBits!C368&_DestuffedBits!C369&_DestuffedBits!C370&_DestuffedBits!C371&_DestuffedBits!C372&_DestuffedBits!C373&_DestuffedBits!C374&_DestuffedBits!C375&_DestuffedBits!C376&_DestuffedBits!C377&_DestuffedBits!C378&_DestuffedBits!C379&_DestuffedBits!C380&_DestuffedBits!C381&_DestuffedBits!C382&_DestuffedBits!C383&_DestuffedBits!C384&_DestuffedBits!C385 | F38: =Fields!J34 | G38: =Fields!K34
A39: FSW | B39: FSW dynamic data addr | C39: 256 | D39: 32 | E39: =_DestuffedBits!C386&_DestuffedBits!C387&_DestuffedBits!C388&_DestuffedBits!C389&_DestuffedBits!C390&_DestuffedBits!C391&_DestuffedBits!C392&_DestuffedBits!C393&_DestuffedBits!C394&_DestuffedBits!C395&_DestuffedBits!C396&_DestuffedBits!C397&_DestuffedBits!C398&_DestuffedBits!C399&_DestuffedBits!C400&_DestuffedBits!C401&_DestuffedBits!C402&_DestuffedBits!C403&_DestuffedBits!C404&_DestuffedBits!C405&_DestuffedBits!C406&_DestuffedBits!C407&_DestuffedBits!C408&_DestuffedBits!C409&_DestuffedBits!C410&_DestuffedBits!C411&_DestuffedBits!C412&_DestuffedBits!C413&_DestuffedBits!C414&_DestuffedBits!C415&_DestuffedBits!C416&_DestuffedBits!C417 | F39: =Fields!J35 | G39: =Fields!K35
A40: FSW | B40: SD Write Pointer Beacon | C40: 288 | D40: 32 | E40: =_DestuffedBits!C418&_DestuffedBits!C419&_DestuffedBits!C420&_DestuffedBits!C421&_DestuffedBits!C422&_DestuffedBits!C423&_DestuffedBits!C424&_DestuffedBits!C425&_DestuffedBits!C426&_DestuffedBits!C427&_DestuffedBits!C428&_DestuffedBits!C429&_DestuffedBits!C430&_DestuffedBits!C431&_DestuffedBits!C432&_DestuffedBits!C433&_DestuffedBits!C434&_DestuffedBits!C435&_DestuffedBits!C436&_DestuffedBits!C437&_DestuffedBits!C438&_DestuffedBits!C439&_DestuffedBits!C440&_DestuffedBits!C441&_DestuffedBits!C442&_DestuffedBits!C443&_DestuffedBits!C444&_DestuffedBits!C445&_DestuffedBits!C446&_DestuffedBits!C447&_DestuffedBits!C448&_DestuffedBits!C449 | F40: =Fields!J36 | G40: =Fields!K36
...

Sheet CRC_Check
A1: Computed CRC-16/X.25 over destuffed payload bits (positions 1..2176): | B1: =DEC2HEX(_xlfn.BITXOR(G2182,65535),4)
A2: Transmitted FCS (destuffed positions 2177..2192, little-endian): | B2: =DEC2HEX(D2,4) | D2: =E2+F2*256 | E2: =_DestuffedBits!C2178*1+_DestuffedBits!C2179*2+_DestuffedBits!C2180*4+_DestuffedBits!C2181*8+_DestuffedBits!C2182*16+_DestuffedBits!C2183*32+_DestuffedBits!C2184*64+_DestuffedBits!C2185*128 | F2: =_DestuffedBits!C2186*1+_DestuffedBits!C2187*2+_DestuffedBits!C2188*4+_DestuffedBits!C2189*8+_DestuffedBits!C2190*16+_DestuffedBits!C2191*32+_DestuffedBits!C2192*64+_DestuffedBits!C2193*128
A3: CRC check: | B3: =IF(B1=B2,"PASS","FAIL")
A5: BitPos(payload) | B5: PayloadBit | C5: crc_prev | D5: lsb | E5: shifted | F5: xorflag | G5: crc_new
A6: 0 | G6: 65535
A7: 1 | B7: =_DestuffedBits!C2 | C7: =G6 | D7: =_xlfn.BITAND(C7,1) | E7: =_xlfn.BITRSHIFT(C7,1) | F7: =_xlfn.BITXOR(D7,B7) | G7: =IF(F7=1,_xlfn.BITXOR(E7,33800),E7)
A8: 2 | B8: =_DestuffedBits!C3 | C8: =G7 | D8: =_xlfn.BITAND(C8,1) | E8: =_xlfn.BITRSHIFT(C8,1) | F8: =_xlfn.BITXOR(D8,B8) | G8: =IF(F8=1,_xlfn.BITXOR(E8,33800),E8)
A9: 3 | B9: =_DestuffedBits!C4 | C9: =G8 | D9: =_xlfn.BITAND(C9,1) | E9: =_xlfn.BITRSHIFT(C9,1) | F9: =_xlfn.BITXOR(D9,B9) | G9: =IF(F9=1,_xlfn.BITXOR(E9,33800),E9)
A10: 4 | B10: =_DestuffedBits!C5 | C10: =G9 | D10: =_xlfn.BITAND(C10,1) | E10: =_xlfn.BITRSHIFT(C10,1) | F10: =_xlfn.BITXOR(D10,B10) | G10: =IF(F10=1,_xlfn.BITXOR(E10,33800),E10)
A11: 5 | B11: =_DestuffedBits!C6 | C11: =G10 | D11: =_xlfn.BITAND(C11,1) | E11: =_xlfn.BITRSHIFT(C11,1) | F11: =_xlfn.BITXOR(D11,B11) | G11: =IF(F11=1,_xlfn.BITXOR(E11,33800),E11)
A12: 6 | B12: =_DestuffedBits!C7 | C12: =G11 | D12: =_xlfn.BITAND(C12,1) | E12: =_xlfn.BITRSHIFT(C12,1) | F12: =_xlfn.BITXOR(D12,B12) | G12: =IF(F12=1,_xlfn.BITXOR(E12,33800),E12)
A13: 7 | B13: =_DestuffedBits!C8 | C13: =G12 | D13: =_xlfn.BITAND(C13,1) | E13: =_xlfn.BITRSHIFT(C13,1) | F13: =_xlfn.BITXOR(D13,B13) | G13: =IF(F13=1,_xlfn.BITXOR(E13,33800),E13)
A14: 8 | B14: =_DestuffedBits!C9 | C14: =G13 | D14: =_xlfn.BITAND(C14,1) | E14: =_xlfn.BITRSHIFT(C14,1) | F14: =_xlfn.BITXOR(D14,B14) | G14: =IF(F14=1,_xlfn.BITXOR(E14,33800),E14)
A15: 9 | B15: =_DestuffedBits!C10 | C15: =G14 | D15: =_xlfn.BITAND(C15,1) | E15: =_xlfn.BITRSHIFT(C15,1) | F15: =_xlfn.BITXOR(D15,B15) | G15: =IF(F15=1,_xlfn.BITXOR(E15,33800),E15)
A16: 10 | B16: =_DestuffedBits!C11 | C16: =G15 | D16: =_xlfn.BITAND(C16,1) | E16: =_xlfn.BITRSHIFT(C16,1) | F16: =_xlfn.BITXOR(D16,B16) | G16: =IF(F16=1,_xlfn.BITXOR(E16,33800),E16)
A17: 11 | B17: =_DestuffedBits!C12 | C17: =G16 | D17: =_xlfn.BITAND(C17,1) | E17: =_xlfn.BITRSHIFT(C17,1) | F17: =_xlfn.BITXOR(D17,B17) | G17: =IF(F17=1,_xlfn.BITXOR(E17,33800),E17)
A18: 12 | B18: =_DestuffedBits!C13 | C18: =G17 | D18: =_xlfn.BITAND(C18,1) | E18: =_xlfn.BITRSHIFT(C18,1) | F18: =_xlfn.BITXOR(D18,B18) | G18: =IF(F18=1,_xlfn.BITXOR(E18,33800),E18)
... A2182: 2176 | B2182: =_DestuffedBits!C2177 | C2182: =G2181 | D2182: =_xlfn.BITAND(C2182,1) | E2182: =_xlfn.BITRSHIFT(C2182,1) | F2182: =_xlfn.BITXOR(D2182,B2182) | G2182: =IF(F2182=1,_xlfn.BITXOR(E2182,33800),E2182)

Sheet Fields
A1: FieldIndex | B1: Subsystem | C1: ItemName | D1: OffsetBit(Info) | E1: BitLen | F1: Endian | G1: DType | H1: RawUnsigned | I1: Value(signed/float) | J1: ReadableValue | K1: LookupTable
A2: 0 | B2: FSW | C2: APID | D2: 0 | E2: 8 | F2: BE | G2: uint8_t | H2: =_DestuffedBits!C130*128+_DestuffedBits!C131*64+_DestuffedBits!C132*32+_DestuffedBits!C133*16+_DestuffedBits!C134*8+_DestuffedBits!C135*4+_DestuffedBits!C136*2+_DestuffedBits!C137*1 | I2: =H2 | J2: =I2 | K2: -
A3: 1 | B3: FSW | C3: First boot | D3: 8 | E3: 1 | F3: BE | G3: uint8_t | H3: =_DestuffedBits!C138*1 | I3: =H3 | J3: =IF(H3=0,"OFF",IF(H3=1,"ON",H3&" (unlisted)")) | K3: (assumed 0=OFF/1=ON, no field-specific description)
A4: 2 | B4: FSW | C4: Going to ADCS commission | D4: 9 | E4: 1 | F4: BE | G4: uint8_t | H4: =_DestuffedBits!C139*1 | I4: =H4 | J4: =IF(H4=0,"OFF",IF(H4=1,"ON",H4&" (unlisted)")) | K4: (assumed 0=OFF/1=ON, no field-specific description)
A5: 3 | B5: FSW | C5: adcs_commissioned | D5: 10 | E5: 1 | F5: BE | G5: uint8_t | H5: =_DestuffedBits!C140*1 | I5: =H5 | J5: =IF(H5=0,"OFF",IF(H5=1,"ON",H5&" (unlisted)")) | K5: (assumed 0=OFF/1=ON, no field-specific description)
A6: 4 | B6: FSW | C6: MAG | D6: 11 | E6: 1 | F6: BE | G6: uint8_t | H6: =_DestuffedBits!C141*1 | I6: =H6 | J6: =IF(H6=0,"OFF",IF(H6=1,"ON",H6&" (unlisted)")) | K6: (assumed 0=OFF/1=ON, no field-specific description)
A7: 5 | B7: FSW | C7: SP1 | D7: 12 | E7: 1 | F7: BE | G7: uint8_t | H7: =_DestuffedBits!C142*1 | I7: =H7 | J7: =IF(H7=0,"OFF",IF(H7=1,"ON",H7&" (unlisted)")) | K7: (assumed 0=OFF/1=ON, no field-specific description)
A8: 6 | B8: FSW | C8: SP2 | D8: 13 | E8: 1 | F8: BE | G8: uint8_t | H8: =_DestuffedBits!C143*1 | I8: =H8 | J8: =IF(H8=0,"OFF",IF(H8=1,"ON",H8&" (unlisted)")) | K8: (assumed 0=OFF/1=ON, no field-specific description)
A9: 7 | B9: FSW | C9: VHF | D9: 14 | E9: 1 | F9: BE | G9: uint8_t | H9: =_DestuffedBits!C144*1 | I9: =H9 | J9: =IF(H9=0,"OFF",IF(H9=1,"ON",H9&" (unlisted)")) | K9: (assumed 0=OFF/1=ON, no field-specific description)
A10: 8 | B10: FSW | C10: UHF | D10: 15 | E10: 1 | F10: BE | G10: uint8_t | H10: =_DestuffedBits!C145*1 | I10: =H10 | J10: =IF(H10=0,"OFF",IF(H10=1,"ON",H10&" (unlisted)")) | K10: (assumed 0=OFF/1=ON, no field-specific description)
A11: 9 | B11: FSW | C11: sys_state - factory reset | D11: 16 | E11: 1 | F11: BE | G11: uint8_t | H11: =_DestuffedBits!C146*1 | I11: =H11 | J11: =IF(H11=0,"OFF",IF(H11=1,"ON",H11&" (unlisted)")) | K11: (assumed 0=OFF/1=ON, no field-specific description)
A12: 10 | B12: FSW | C12: sys_state - reset | D12: 17 | E12: 1 | F12: BE | G12: uint8_t | H12: =_DestuffedBits!C147*1 | I12: =H12 | J12: =IF(H12=0,"OFF",IF(H12=1,"ON",H12&" (unlisted)")) | K12: (assumed 0=OFF/1=ON, no field-specific description)
A13: 11 | B13: FSW | C13: Main SD select | D13: 18 | E13: 1 | F13: BE | G13: uint8_t | H13: =_DestuffedBits!C148*1 | I13: =H13 | J13: =IF(H13=0,"OFF",IF(H13=1,"ON",H13&" (unlisted)")) | K13: (assumed 0=OFF/1=ON, no field-specific description)
A14: 12 | B14: FSW | C14: Nominal | D14: 19 | E14: 1 | F14: BE | G14: uint8_t | H14: =_DestuffedBits!C149*1 | I14: =H14 | J14: =IF(H14=0,"containgency state(safe, phoneix)",IF(H14=1,"nominal state(charging, COMM, SCI)",H14&" (unlisted)")) | K14: 1: nominal state(charging, COMM, SCI), 0: containgency state(safe, phoneix)
A15: 13 | B15: FSW | C15: (reserved) | D15: 20 | E15: 4 | F15: BE | G15: uint8_t | H15: =_DestuffedBits!C150*8+_DestuffedBits!C151*4+_DestuffedBits!C152*2+_DestuffedBits!C153*1 | I15: =H15 | J15: =I15 | K15: -
A16: 14 | B16: FSW | C16: OBC Time | D16: 24 | E16: 32 | F16: LE | G16: uint32_t | H16: =_DestuffedBits!C154*128+_DestuffedBits!C155*64+_DestuffedBits!C156*32+_DestuffedBits!C157*16+_DestuffedBits!C158*8+_DestuffedBits!C159*4+_DestuffedBits!C160*2+_DestuffedBits!C161*1+_DestuffedBits!C162*32768+_DestuffedBits!C163*16384+_DestuffedBits!C164*8192+_DestuffedBits!C165*4096+_DestuffedBits!C166*2048+_DestuffedBits!C167*1024+_DestuffedBits!C168*512+_DestuffedBits!C169*256+_DestuffedBits!C170*8388608+_DestuffedBits!C171*4194304+_DestuffedBits!C172*2097152+_DestuffedBits!C173*1048576+_DestuffedBits!C174*524288+_DestuffedBits!C175*262144+_DestuffedBits!C176*131072+_DestuffedBits!C177*65536+_DestuffedBits!C178*2147483648+_DestuffedBits!C179*1073741824+_DestuffedBits!C180*536870912+_DestuffedBits!C181*268435456+_DestuffedBits!C182*134217728+_DestuffedBits!C183*67108864+_DestuffedBits!C184*33554432+_DestuffedBits!C185*16777216 | I16: =H16 | J16: =I16&" s" | K16: transform:obc_time {'unit': 's', 'display_format': 'YYYY-MM-DD HH:mm:ss', 'timezone': 'Asia/Taipei', 'offset_hours': 8}
A17: 15 | B17: FSW | C17: Current Mode | D17: 56 | E17: 8 | F17: BE | G17: uint8_t | H17: =_DestuffedBits!C186*128+_DestuffedBits!C187*64+_DestuffedBits!C188*32+_DestuffedBits!C189*16+_DestuffedBits!C190*8+_DestuffedBits!C191*4+_DestuffedBits!C192*2+_DestuffedBits!C193*1 | I17: =H17 | J17: =IF(H17=0,"Phoenix Mode",IF(H17=1,"Safe Mode",IF(H17=2,"Charging Mode",IF(H17=3,"Communication Xband Mode",IF(H17=10,"Science HyperSCAN Mode",IF(H17=11,"Science CIP Mode",IF(H17=255,"Reentry Mode",H17&" (unlisted)"))))))) | K17: Operation Mode Defined (hex. value): / 0 - Phoenix Mode / 1 - Safe Mode / 2 - Charging Mode / 3 - Communication Xband Mode / A - Science HyperSCAN Mode / B - Science CIP Mode / FF - Reentry Mode
A18: 16 | B18: FSW | C18: EPS onoff state | D18: 64 | E18: 1 | F18: BE | G18: uint8_t | H18: =_DestuffedBits!C194*1 | I18: =H18 | J18: =IF(H18=0,"off",IF(H18=1,"on",H18&" (unlisted)")) | K18: 0:off/1:on
A19: 17 | B19: FSW | C19: ADCS onoff state | D19: 65 | E19: 1 | F19: BE | G19: uint8_t | H19: =_DestuffedBits!C195*1 | I19: =H19 | J19: =IF(H19=0,"off",IF(H19=1,"on",H19&" (unlisted)")) | K19: 0:off/1:on
A20: 18 | B20: FSW | C20: UHF onoff state | D20: 66 | E20: 1 | F20: BE | G20: uint8_t | H20: =_DestuffedBits!C196*1 | I20: =H20 | J20: =IF(H20=0,"off",IF(H20=1,"on",H20&" (unlisted)")) | K20: 0:off/1:on
A21: 19 | B21: FSW | C21: Xband onoff state | D21: 67 | E21: 1 | F21: BE | G21: uint8_t | H21: =_DestuffedBits!C197*1 | I21: =H21 | J21: =IF(H21=0,"off",IF(H21=1,"on",H21&" (unlisted)")) | K21: 0:off/1:on
A22: 20 | B22: FSW | C22: CIP onoff state | D22: 68 | E22: 1 | F22: BE | G22: uint8_t | H22: =_DestuffedBits!C198*1 | I22: =H22 | J22: =IF(H22=0,"off",IF(H22=1,"on",H22&" (unlisted)")) | K22: 0:off/1:on
A23: 21 | B23: FSW | C23: HyperSCAN onoff state | D23: 69 | E23: 1 | F23: BE | G23: uint8_t | H23: =_DestuffedBits!C199*1 | I23: =H23 | J23: =IF(H23=0,"off",IF(H23=1,"on",H23&" (unlisted)")) | K23: 0:off/1:on
A24: 22 | B24: FSW | C24: SEUV onoff state | D24: 70 | E24: 1 | F24: BE | G24: uint8_t | H24: =_DestuffedBits!C200*1 | I24: =H24 | J24: =IF(H24=0,"off",IF(H24=1,"on",H24&" (unlisted)")) | K24: 0:off/1:on
A25: 23 | B25: FSW | C25: APRS onoff state | D25: 71 | E25: 1 | F25: BE | G25: uint8_t | H25: =_DestuffedBits!C201*1 | I25: =H25 | J25: =IF(H25=0,"off",IF(H25=1,"on",H25&" (unlisted)")) | K25: 0:off/1:on
A26: 24 | B26: FSW | C26: FSW Reboot Count | D26: 72 | E26: 16 | F26: LE | G26: uint16_t | H26: =_DestuffedBits!C202*128+_DestuffedBits!C203*64+_DestuffedBits!C204*32+_DestuffedBits!C205*16+_DestuffedBits!C206*8+_DestuffedBits!C207*4+_DestuffedBits!C208*2+_DestuffedBits!C209*1+_DestuffedBits!C210*32768+_DestuffedBits!C211*16384+_DestuffedBits!C212*8192+_DestuffedBits!C213*4096+_DestuffedBits!C214*2048+_DestuffedBits!C215*1024+_DestuffedBits!C216*512+_DestuffedBits!C217*256 | I26: =H26 | J26: =I26 | K26: -
A27: 25 | B27: FSW | C27: CMD Accept Count | D27: 88 | E27: 16 | F27: LE | G27: uint16_t | H27: =_DestuffedBits!C218*128+_DestuffedBits!C219*64+_DestuffedBits!C220*32+_DestuffedBits!C221*16+_DestuffedBits!C222*8+_DestuffedBits!C223*4+_DestuffedBits!C224*2+_DestuffedBits!C225*1+_DestuffedBits!C226*32768+_DestuffedBits!C227*16384+_DestuffedBits!C228*8192+_DestuffedBits!C229*4096+_DestuffedBits!C230*2048+_DestuffedBits!C231*1024+_DestuffedBits!C232*512+_DestuffedBits!C233*256 | I27: =H27 | J27: =I27 | K27: -
A28: 26 | B28: FSW | C28: CMD Reject Count | D28: 104 | E28: 16 | F28: LE | G28: uint16_t | H28: =_DestuffedBits!C234*128+_DestuffedBits!C235*64+_DestuffedBits!C236*32+_DestuffedBits!C237*16+_DestuffedBits!C238*8+_DestuffedBits!C239*4+_DestuffedBits!C240*2+_DestuffedBits!C241*1+_DestuffedBits!C242*32768+_DestuffedBits!C243*16384+_DestuffedBits!C244*8192+_DestuffedBits!C245*4096+_DestuffedBits!C246*2048+_DestuffedBits!C247*1024+_DestuffedBits!C248*512+_DestuffedBits!C249*256 | I28: =H28 | J28: =I28 | K28: -
A29: 27 | B29: FSW | C29: Last packet send | D29: 120 | E29: 32 | F29: LE | G29: uint32_t | H29: =_DestuffedBits!C250*128+_DestuffedBits!C251*64+_DestuffedBits!C252*32+_DestuffedBits!C253*16+_DestuffedBits!C254*8+_DestuffedBits!C255*4+_DestuffedBits!C256*2+_DestuffedBits!C257*1+_DestuffedBits!C258*32768+_DestuffedBits!C259*16384+_DestuffedBits!C260*8192+_DestuffedBits!C261*4096+_DestuffedBits!C262*2048+_DestuffedBits!C263*1024+_DestuffedBits!C264*512+_DestuffedBits!C265*256+_DestuffedBits!C266*8388608+_DestuffedBits!C267*4194304+_DestuffedBits!C268*2097152+_DestuffedBits!C269*1048576+_DestuffedBits!C270*524288+_DestuffedBits!C271*262144+_DestuffedBits!C272*131072+_DestuffedBits!C273*65536+_DestuffedBits!C274*2147483648+_DestuffedBits!C275*1073741824+_DestuffedBits!C276*536870912+_DestuffedBits!C277*268435456+_DestuffedBits!C278*134217728+_DestuffedBits!C279*67108864+_DestuffedBits!C280*33554432+_DestuffedBits!C281*16777216 | I29: =H29 | J29: =I29 | K29: -
A30: 28 | B30: FSW | C30: Last packet send time | D30: 152 | E30: 32 | F30: LE | G30: uint32_t | H30: =_DestuffedBits!C282*128+_DestuffedBits!C283*64+_DestuffedBits!C284*32+_DestuffedBits!C285*16+_DestuffedBits!C286*8+_DestuffedBits!C287*4+_DestuffedBits!C288*2+_DestuffedBits!C289*1+_DestuffedBits!C290*32768+_DestuffedBits!C291*16384+_DestuffedBits!C292*8192+_DestuffedBits!C293*4096+_DestuffedBits!C294*2048+_DestuffedBits!C295*1024+_DestuffedBits!C296*512+_DestuffedBits!C297*256+_DestuffedBits!C298*8388608+_DestuffedBits!C299*4194304+_DestuffedBits!C300*2097152+_DestuffedBits!C301*1048576+_DestuffedBits!C302*524288+_DestuffedBits!C303*262144+_DestuffedBits!C304*131072+_DestuffedBits!C305*65536+_DestuffedBits!C306*2147483648+_DestuffedBits!C307*1073741824+_DestuffedBits!C308*536870912+_DestuffedBits!C309*268435456+_DestuffedBits!C310*134217728+_DestuffedBits!C311*67108864+_DestuffedBits!C312*33554432+_DestuffedBits!C313*16777216 | I30: =H30 | J30: =I30 | K30: -
A31: 29 | B31: FSW | C31: Last Accept CMD Time | D31: 184 | E31: 32 | F31: LE | G31: uint32_t | H31: =_DestuffedBits!C314*128+_DestuffedBits!C315*64+_DestuffedBits!C316*32+_DestuffedBits!C317*16+_DestuffedBits!C318*8+_DestuffedBits!C319*4+_DestuffedBits!C320*2+_DestuffedBits!C321*1+_DestuffedBits!C322*32768+_DestuffedBits!C323*16384+_DestuffedBits!C324*8192+_DestuffedBits!C325*4096+_DestuffedBits!C326*2048+_DestuffedBits!C327*1024+_DestuffedBits!C328*512+_DestuffedBits!C329*256+_DestuffedBits!C330*8388608+_DestuffedBits!C331*4194304+_DestuffedBits!C332*2097152+_DestuffedBits!C333*1048576+_DestuffedBits!C334*524288+_DestuffedBits!C335*262144+_DestuffedBits!C336*131072+_DestuffedBits!C337*65536+_DestuffedBits!C338*2147483648+_DestuffedBits!C339*1073741824+_DestuffedBits!C340*536870912+_DestuffedBits!C341*268435456+_DestuffedBits!C342*134217728+_DestuffedBits!C343*67108864+_DestuffedBits!C344*33554432+_DestuffedBits!C345*16777216 | I31: =H31 | J31: =I31 | K31: -
A32: 30 | B32: FSW | C32: Last Accept CMD Type OPCODE | D32: 216 | E32: 4 | F32: LE | G32: uint8_t | H32: =_DestuffedBits!C346*8+_DestuffedBits!C347*4+_DestuffedBits!C348*2+_DestuffedBits!C349*1 | I32: =H32 | J32: =I32 | K32: -
A33: 31 | B33: FSW | C33: Last Accept CMD Type APID | D33: 220 | E33: 4 | F33: LE | G33: uint8_t | H33: =_DestuffedBits!C350*8+_DestuffedBits!C351*4+_DestuffedBits!C352*2+_DestuffedBits!C353*1 | I33: =H33 | J33: =I33 | K33: -
A34: 32 | B34: FSW | C34: FSW static data addr | D34: 224 | E34: 32 | F34: LE | G34: uint32_t | H34: =_DestuffedBits!C354*128+_DestuffedBits!C355*64+_DestuffedBits!C356*32+_DestuffedBits!C357*16+_DestuffedBits!C358*8+_DestuffedBits!C359*4+_DestuffedBits!C360*2+_DestuffedBits!C361*1+_DestuffedBits!C362*32768+_DestuffedBits!C363*16384+_DestuffedBits!C364*8192+_DestuffedBits!C365*4096+_DestuffedBits!C366*2048+_DestuffedBits!C367*1024+_DestuffedBits!C368*512+_DestuffedBits!C369*256+_DestuffedBits!C370*8388608+_DestuffedBits!C371*4194304+_DestuffedBits!C372*2097152+_DestuffedBits!C373*1048576+_DestuffedBits!C374*524288+_DestuffedBits!C375*262144+_DestuffedBits!C376*131072+_DestuffedBits!C377*65536+_DestuffedBits!C378*2147483648+_DestuffedBits!C379*1073741824+_DestuffedBits!C380*536870912+_DestuffedBits!C381*268435456+_DestuffedBits!C382*134217728+_DestuffedBits!C383*67108864+_DestuffedBits!C384*33554432+_DestuffedBits!C385*16777216 | I34: =H34 | J34: =I34 | K34: -
A35: 33 | B35: FSW | C35: FSW dynamic data addr | D35: 256 | E35: 32 | F35: LE | G35: uint32_t | H35: =_DestuffedBits!C386*128+_DestuffedBits!C387*64+_DestuffedBits!C388*32+_DestuffedBits!C389*16+_DestuffedBits!C390*8+_DestuffedBits!C391*4+_DestuffedBits!C392*2+_DestuffedBits!C393*1+_DestuffedBits!C394*32768+_DestuffedBits!C395*16384+_DestuffedBits!C396*8192+_DestuffedBits!C397*4096+_DestuffedBits!C398*2048+_DestuffedBits!C399*1024+_DestuffedBits!C400*512+_DestuffedBits!C401*256+_DestuffedBits!C402*8388608+_DestuffedBits!C403*4194304+_DestuffedBits!C404*2097152+_DestuffedBits!C405*1048576+_DestuffedBits!C406*524288+_DestuffedBits!C407*262144+_DestuffedBits!C408*131072+_DestuffedBits!C409*65536+_DestuffedBits!C410*2147483648+_DestuffedBits!C411*1073741824+_DestuffedBits!C412*536870912+_DestuffedBits!C413*268435456+_DestuffedBits!C414*134217728+_DestuffedBits!C415*67108864+_DestuffedBits!C416*33554432+_DestuffedBits!C417*16777216 | I35: =H35 | J35: =I35 | K35: -
